Workbook

Sheet C_Outstanding Payment
A2: DAILY PAYMENT SCHEDULE | B2: SBI | C2: IDBI | D2: BOI | E2: PAYABLE AMOUNT (INR) | G2: MONTHLY PAYABLE SUMMARY | H2: AMOUNT (INR)
A3: =WORKDAY(TODAY(), 0) -> 46178 | B3: =SUMIFS('LC-Final List'!$W:$W,'LC-Final List'!$Y:$Y,$A3,'LC-Final List'!$AE:$AE,"*Unpaid*",'LC-Final List'!$E:$E,B$2) -> 103736160 | C3: =SUMIFS('LC-Final List'!$W:$W,'LC-Final List'!$Y:$Y,$A3,'LC-Final List'!$AE:$AE,"*Unpaid*",'LC-Final List'!$E:$E,C$2) -> 0 | D3: =SUMIFS('LC-Final List'!$W:$W,'LC-Final List'!$Y:$Y,$A3,'LC-Final List'!$AE:$AE,"*Unpaid*",'LC-Final List'!$E:$E,D$2) -> 0 | E3: =SUMIFS('LC-Final List'!$W:$W,'LC-Final List'!$Y:$Y,$A3,'LC-Final List'!$AE:$AE,"*Unpaid*") -> 103736160 | G3: January26 | H3: =SUMIFS('LC-Final List'!$W:$W, 'LC-Final List'!$AC:$AC, G3, 'LC-Final List'!$AE:$AE, "*Unpaid*") -> 0
A4: =WORKDAY(TODAY(), 1) -> 46181 | B4: =SUMIFS('LC-Final List'!$W:$W,'LC-Final List'!$Y:$Y,$A4,'LC-Final List'!$AE:$AE,"*Unpaid*",'LC-Final List'!$E:$E,B$2) -> 1.1980314e+08 | C4: =SUMIFS('LC-Final List'!$W:$W,'LC-Final List'!$Y:$Y,$A4,'LC-Final List'!$AE:$AE,"*Unpaid*",'LC-Final List'!$E:$E,C$2) -> 0 | D4: =SUMIFS('LC-Final List'!$W:$W,'LC-Final List'!$Y:$Y,$A4,'LC-Final List'!$AE:$AE,"*Unpaid*",'LC-Final List'!$E:$E,D$2) -> 0 | E4: =SUMIFS('LC-Final List'!$W:$W,'LC-Final List'!$Y:$Y,$A4,'LC-Final List'!$AE:$AE,"*Unpaid*") -> 1.1980314e+08 | G4: February26 | H4: =SUMIFS('LC-Final List'!$W:$W, 'LC-Final List'!$AC:$AC, G4, 'LC-Final List'!$AE:$AE, "*Unpaid*") -> 0
A5: =WORKDAY(TODAY(), 2) -> 46182 | B5: =SUMIFS('LC-Final List'!$W:$W,'LC-Final List'!$Y:$Y,$A5,'LC-Final List'!$AE:$AE,"*Unpaid*",'LC-Final List'!$E:$E,B$2) -> 4.5797035e+08 | C5: =SUMIFS('LC-Final List'!$W:$W,'LC-Final List'!$Y:$Y,$A5,'LC-Final List'!$AE:$AE,"*Unpaid*",'LC-Final List'!$E:$E,C$2) -> 0 | D5: =SUMIFS('LC-Final List'!$W:$W,'LC-Final List'!$Y:$Y,$A5,'LC-Final List'!$AE:$AE,"*Unpaid*",'LC-Final List'!$E:$E,D$2) -> 72808013 | E5: =SUMIFS('LC-Final List'!$W:$W,'LC-Final List'!$Y:$Y,$A5,'LC-Final List'!$AE:$AE,"*Unpaid*") -> 5.3077836e+08 | G5: March26 | H5: =SUMIFS('LC-Final List'!$W:$W, 'LC-Final List'!$AC:$AC, G5, 'LC-Final List'!$AE:$AE, "*Unpaid*") -> 0
A6: =WORKDAY(TODAY(), 3) -> 46183 | B6: =SUMIFS('LC-Final List'!$W:$W,'LC-Final List'!$Y:$Y,$A6,'LC-Final List'!$AE:$AE,"*Unpaid*",'LC-Final List'!$E:$E,B$2) -> 0 | C6: =SUMIFS('LC-Final List'!$W:$W,'LC-Final List'!$Y:$Y,$A6,'LC-Final List'!$AE:$AE,"*Unpaid*",'LC-Final List'!$E:$E,C$2) -> 0 | D6: =SUMIFS('LC-Final List'!$W:$W,'LC-Final List'!$Y:$Y,$A6,'LC-Final List'!$AE:$AE,"*Unpaid*",'LC-Final List'!$E:$E,D$2) -> 0 | E6: =SUMIFS('LC-Final List'!$W:$W,'LC-Final List'!$Y:$Y,$A6,'LC-Final List'!$AE:$AE,"*Unpaid*") -> 0 | G6: April26 | H6: =SUMIFS('LC-Final List'!$W:$W, 'LC-Final List'!$AC:$AC, G6, 'LC-Final List'!$AE:$AE, "*Unpaid*") -> 0
A7: =WORKDAY(TODAY(), 4) -> 46184 | B7: =SUMIFS('LC-Final List'!$W:$W,'LC-Final List'!$Y:$Y,$A7,'LC-Final List'!$AE:$AE,"*Unpaid*",'LC-Final List'!$E:$E,B$2) -> 2.4195292e+08 | C7: =SUMIFS('LC-Final List'!$W:$W,'LC-Final List'!$Y:$Y,$A7,'LC-Final List'!$AE:$AE,"*Unpaid*",'LC-Final List'!$E:$E,C$2) -> 0 | D7: =SUMIFS('LC-Final List'!$W:$W,'LC-Final List'!$Y:$Y,$A7,'LC-Final List'!$AE:$AE,"*Unpaid*",'LC-Final List'!$E:$E,D$2) -> 0 | E7: =SUMIFS('LC-Final List'!$W:$W,'LC-Final List'!$Y:$Y,$A7,'LC-Final List'!$AE:$AE,"*Unpaid*") -> 2.4195292e+08 | G7: May26 | H7: =SUMIFS('LC-Final List'!$W:$W, 'LC-Final List'!$AC:$AC, G7, 'LC-Final List'!$AE:$AE, "*Unpaid*") -> 0
A8: =WORKDAY(TODAY(), 5) -> 46185 | B8: =SUMIFS('LC-Final List'!$W:$W,'LC-Final List'!$Y:$Y,$A8,'LC-Final List'!$AE:$AE,"*Unpaid*",'LC-Final List'!$E:$E,B$2) -> 3.7510745e+08 | C8: =SUMIFS('LC-Final List'!$W:$W,'LC-Final List'!$Y:$Y,$A8,'LC-Final List'!$AE:$AE,"*Unpaid*",'LC-Final List'!$E:$E,C$2) -> 0 | D8: =SUMIFS('LC-Final List'!$W:$W,'LC-Final List'!$Y:$Y,$A8,'LC-Final List'!$AE:$AE,"*Unpaid*",'LC-Final List'!$E:$E,D$2) -> 169992000 | E8: =SUMIFS('LC-Final List'!$W:$W,'LC-Final List'!$Y:$Y,$A8,'LC-Final List'!$AE:$AE,"*Unpaid*") -> 5.4509945e+08 | G8: 46174 | H8: =SUMIFS('LC-Final List'!$W:$W, 'LC-Final List'!$AC:$AC, G8, 'LC-Final List'!$AE:$AE, "*Unpaid*") -> 3.038332e+09
A9: =WORKDAY(TODAY(), 6) -> 46188 | B9: =SUMIFS('LC-Final List'!$W:$W,'LC-Final List'!$Y:$Y,$A9,'LC-Final List'!$AE:$AE,"*Unpaid*",'LC-Final List'!$E:$E,B$2) -> 3.7662287e+08 | C9: =SUMIFS('LC-Final List'!$W:$W,'LC-Final List'!$Y:$Y,$A9,'LC-Final List'!$AE:$AE,"*Unpaid*",'LC-Final List'!$E:$E,C$2) -> 0 | D9: =SUMIFS('LC-Final List'!$W:$W,'LC-Final List'!$Y:$Y,$A9,'LC-Final List'!$AE:$AE,"*Unpaid*",'LC-Final List'!$E:$E,D$2) -> 232502400 | E9: =SUMIFS('LC-Final List'!$W:$W,'LC-Final List'!$Y:$Y,$A9,'LC-Final List'!$AE:$AE,"*Unpaid*") -> 6.0912527e+08 | G9: 46204 | H9: =SUMIFS('LC-Final List'!$W:$W, 'LC-Final List'!$AC:$AC, G9, 'LC-Final List'!$AE:$AE, "*Unpaid*") -> 1.2268206e+09
A10: =WORKDAY(TODAY(), 7) -> 46189 | B10: =SUMIFS('LC-Final List'!$W:$W,'LC-Final List'!$Y:$Y,$A10,'LC-Final List'!$AE:$AE,"*Unpaid*",'LC-Final List'!$E:$E,B$2) -> 76898304 | C10: =SUMIFS('LC-Final List'!$W:$W,'LC-Final List'!$Y:$Y,$A10,'LC-Final List'!$AE:$AE,"*Unpaid*",'LC-Final List'!$E:$E,C$2) -> 0 | D10: =SUMIFS('LC-Final List'!$W:$W,'LC-Final List'!$Y:$Y,$A10,'LC-Final List'!$AE:$AE,"*Unpaid*",'LC-Final List'!$E:$E,D$2) -> 0 | E10: =SUMIFS('LC-Final List'!$W:$W,'LC-Final List'!$Y:$Y,$A10,'LC-Final List'!$AE:$AE,"*Unpaid*") -> 76898304 | G10: 46235 | H10: =SUMIFS('LC-Final List'!$W:$W, 'LC-Final List'!$AC:$AC, G10, 'LC-Final List'!$AE:$AE, "*Unpaid*") -> 28999680
A11: =WORKDAY(TODAY(), 8) -> 46190 | B11: =SUMIFS('LC-Final List'!$W:$W,'LC-Final List'!$Y:$Y,$A11,'LC-Final List'!$AE:$AE,"*Unpaid*",'LC-Final List'!$E:$E,B$2) -> 2.6303468e+08 | C11: =SUMIFS('LC-Final List'!$W:$W,'LC-Final List'!$Y:$Y,$A11,'LC-Final List'!$AE:$AE,"*Unpaid*",'LC-Final List'!$E:$E,C$2) -> 0 | D11: =SUMIFS('LC-Final List'!$W:$W,'LC-Final List'!$Y:$Y,$A11,'LC-Final List'!$AE:$AE,"*Unpaid*",'LC-Final List'!$E:$E,D$2) -> 0 | E11: =SUMIFS('LC-Final List'!$W:$W,'LC-Final List'!$Y:$Y,$A11,'LC-Final List'!$AE:$AE,"*Unpaid*") -> 2.6303468e+08 | G11: 46266 | H11: =SUMIFS('LC-Final List'!$W:$W, 'LC-Final List'!$AC:$AC, G11, 'LC-Final List'!$AE:$AE, "*Unpaid*") -> 122867712
A12: =WORKDAY(TODAY(), 9) -> 46191 | B12: =SUMIFS('LC-Final List'!$W:$W,'LC-Final List'!$Y:$Y,$A12,'LC-Final List'!$AE:$AE,"*Unpaid*",'LC-Final List'!$E:$E,B$2) -> 0 | C12: =SUMIFS('LC-Final List'!$W:$W,'LC-Final List'!$Y:$Y,$A12,'LC-Final List'!$AE:$AE,"*Unpaid*",'LC-Final List'!$E:$E,C$2) -> 0 | D12: =SUMIFS('LC-Final List'!$W:$W,'LC-Final List'!$Y:$Y,$A12,'LC-Final List'!$AE:$AE,"*Unpaid*",'LC-Final List'!$E:$E,D$2) -> 0 | E12: =SUMIFS('LC-Final List'!$W:$W,'LC-Final List'!$Y:$Y,$A12,'LC-Final List'!$AE:$AE,"*Unpaid*") -> 0
A13: =WORKDAY(TODAY(),10) -> 46192 | B13: =SUMIFS('LC-Final List'!$W:$W,'LC-Final List'!$Y:$Y,$A13,'LC-Final List'!$AE:$AE,"*Unpaid*",'LC-Final List'!$E:$E,B$2) -> 0 | C13: =SUMIFS('LC-Final List'!$W:$W,'LC-Final List'!$Y:$Y,$A13,'LC-Final List'!$AE:$AE,"*Unpaid*",'LC-Final List'!$E:$E,C$2) -> 0 | D13: =SUMIFS('LC-Final List'!$W:$W,'LC-Final List'!$Y:$Y,$A13,'LC-Final List'!$AE:$AE,"*Unpaid*",'LC-Final List'!$E:$E,D$2) -> 0 | E13: =SUMIFS('LC-Final List'!$W:$W,'LC-Final List'!$Y:$Y,$A13,'LC-Final List'!$AE:$AE,"*Unpaid*") -> 0
A14: =WORKDAY(TODAY(),11) -> 46195 | B14: =SUMIFS('LC-Final List'!$W:$W,'LC-Final List'!$Y:$Y,$A14,'LC-Final List'!$AE:$AE,"*Unpaid*",'LC-Final List'!$E:$E,B$2) -> 117792000 | C14: =SUMIFS('LC-Final List'!$W:$W,'LC-Final List'!$Y:$Y,$A14,'LC-Final List'!$AE:$AE,"*Unpaid*",'LC-Final List'!$E:$E,C$2) -> 3.5825918e+08 | D14: =SUMIFS('LC-Final List'!$W:$W,'LC-Final List'!$Y:$Y,$A14,'LC-Final List'!$AE:$AE,"*Unpaid*",'LC-Final List'!$E:$E,D$2) -> 0 | E14: =SUMIFS('LC-Final List'!$W:$W,'LC-Final List'!$Y:$Y,$A14,'LC-Final List'!$AE:$AE,"*Unpaid*") -> 4.7605118e+08
A15: =WORKDAY(TODAY(),12) -> 46196 | B15: =SUMIFS('LC-Final List'!$W:$W,'LC-Final List'!$Y:$Y,$A15,'LC-Final List'!$AE:$AE,"*Unpaid*",'LC-Final List'!$E:$E,B$2) -> 6344064 | C15: =SUMIFS('LC-Final List'!$W:$W,'LC-Final List'!$Y:$Y,$A15,'LC-Final List'!$AE:$AE,"*Unpaid*",'LC-Final List'!$E:$E,C$2) -> 0 | D15: =SUMIFS('LC-Final List'!$W:$W,'LC-Final List'!$Y:$Y,$A15,'LC-Final List'!$AE:$AE,"*Unpaid*",'LC-Final List'!$E:$E,D$2) -> 0 | E15: =SUMIFS('LC-Final List'!$W:$W,'LC-Final List'!$Y:$Y,$A15,'LC-Final List'!$AE:$AE,"*Unpaid*") -> 6344064
A16: =WORKDAY(TODAY(),13) -> 46197 | B16: =SUMIFS('LC-Final List'!$W:$W,'LC-Final List'!$Y:$Y,$A16,'LC-Final List'!$AE:$AE,"*Unpaid*",'LC-Final List'!$E:$E,B$2) -> 0 | C16: =SUMIFS('LC-Final List'!$W:$W,'LC-Final List'!$Y:$Y,$A16,'LC-Final List'!$AE:$AE,"*Unpaid*",'LC-Final List'!$E:$E,C$2) -> 0 | D16: =SUMIFS('LC-Final List'!$W:$W,'LC-Final List'!$Y:$Y,$A16,'LC-Final List'!$AE:$AE,"*Unpaid*",'LC-Final List'!$E:$E,D$2) -> 0 | E16: =SUMIFS('LC-Final List'!$W:$W,'LC-Final List'!$Y:$Y,$A16,'LC-Final List'!$AE:$AE,"*Unpaid*") -> 0
A17: =WORKDAY(TODAY(),14) -> 46198 | B17: =SUMIFS('LC-Final List'!$W:$W,'LC-Final List'!$Y:$Y,$A17,'LC-Final List'!$AE:$AE,"*Unpaid*",'LC-Final List'!$E:$E,B$2) -> 0 | C17: =SUMIFS('LC-Final List'!$W:$W,'LC-Final List'!$Y:$Y,$A17,'LC-Final List'!$AE:$AE,"*Unpaid*",'LC-Final List'!$E:$E,C$2) -> 0 | D17: =SUMIFS('LC-Final List'!$W:$W,'LC-Final List'!$Y:$Y,$A17,'LC-Final List'!$AE:$AE,"*Unpaid*",'LC-Final List'!$E:$E,D$2) -> 52310822 | E17: =SUMIFS('LC-Final List'!$W:$W,'LC-Final List'!$Y:$Y,$A17,'LC-Final List'!$AE:$AE,"*Unpaid*") -> 52310822
A18: =WORKDAY(TODAY(),15) -> 46199 | B18: =SUMIFS('LC-Final List'!$W:$W,'LC-Final List'!$Y:$Y,$A18,'LC-Final List'!$AE:$AE,"*Unpaid*",'LC-Final List'!$E:$E,B$2) -> 0 | C18: =SUMIFS('LC-Final List'!$W:$W,'LC-Final List'!$Y:$Y,$A18,'LC-Final List'!$AE:$AE,"*Unpaid*",'LC-Final List'!$E:$E,C$2) -> 0 | D18: =SUMIFS('LC-Final List'!$W:$W,'LC-Final List'!$Y:$Y,$A18,'LC-Final List'!$AE:$AE,"*Unpaid*",'LC-Final List'!$E:$E,D$2) -> 0 | E18: =SUMIFS('LC-Final List'!$W:$W,'LC-Final List'!$Y:$Y,$A18,'LC-Final List'!$AE:$AE,"*Unpaid*") -> 0
A19: =WORKDAY(TODAY(),16) -> 46202 | B19: =SUMIFS('LC-Final List'!$W:$W,'LC-Final List'!$Y:$Y,$A19,'LC-Final List'!$AE:$AE,"*Unpaid*",'LC-Final List'!$E:$E,B$2) -> 13197600 | C19: =SUMIFS('LC-Final List'!$W:$W,'LC-Final List'!$Y:$Y,$A19,'LC-Final List'!$AE:$AE,"*Unpaid*",'LC-Final List'!$E:$E,C$2) -> 0 | D19: =SUMIFS('LC-Final List'!$W:$W,'LC-Final List'!$Y:$Y,$A19,'LC-Final List'!$AE:$AE,"*Unpaid*",'LC-Final List'!$E:$E,D$2) -> 0 | E19: =SUMIFS('LC-Final List'!$W:$W,'LC-Final List'!$Y:$Y,$A19,'LC-Final List'!$AE:$AE,"*Unpaid*") -> 13197600
A20: =WORKDAY(TODAY(),17) -> 46203 | B20: =SUMIFS('LC-Final List'!$W:$W,'LC-Final List'!$Y:$Y,$A20,'LC-Final List'!$AE:$AE,"*Unpaid*",'LC-Final List'!$E:$E,B$2) -> 0 | C20: =SUMIFS('LC-Final List'!$W:$W,'LC-Final List'!$Y:$Y,$A20,'LC-Final List'!$AE:$AE,"*Unpaid*",'LC-Final List'!$E:$E,C$2) -> 0 | D20: =SUMIFS('LC-Final List'!$W:$W,'LC-Final List'!$Y:$Y,$A20,'LC-Final List'!$AE:$AE,"*Unpaid*",'LC-Final List'!$E:$E,D$2) -> 0 | E20: =SUMIFS('LC-Final List'!$W:$W,'LC-Final List'!$Y:$Y,$A20,'LC-Final List'!$AE:$AE,"*Unpaid*") -> 0
A21: =WORKDAY(TODAY(),18) -> 46204 | B21: =SUMIFS('LC-Final List'!$W:$W,'LC-Final List'!$Y:$Y,$A21,'LC-Final List'!$AE:$AE,"*Unpaid*",'LC-Final List'!$E:$E,B$2) -> 0 | C21: =SUMIFS('LC-Final List'!$W:$W,'LC-Final List'!$Y:$Y,$A21,'LC-Final List'!$AE:$AE,"*Unpaid*",'LC-Final List'!$E:$E,C$2) -> 0 | D21: =SUMIFS('LC-Final List'!$W:$W,'LC-Final List'!$Y:$Y,$A21,'LC-Final List'!$AE:$AE,"*Unpaid*",'LC-Final List'!$E:$E,D$2) -> 0 | E21: =SUMIFS('LC-Final List'!$W:$W,'LC-Final List'!$Y:$Y,$A21,'LC-Final List'!$AE:$AE,"*Unpaid*") -> 0
A22: =WORKDAY(TODAY(),19) -> 46205 | B22: =SUMIFS('LC-Final List'!$W:$W,'LC-Final List'!$Y:$Y,$A22,'LC-Final List'!$AE:$AE,"*Unpaid*",'LC-Final List'!$E:$E,B$2) -> 0 | C22: =SUMIFS('LC-Final List'!$W:$W,'LC-Final List'!$Y:$Y,$A22,'LC-Final List'!$AE:$AE,"*Unpaid*",'LC-Final List'!$E:$E,C$2) -> 0 | D22: =SUMIFS('LC-Final List'!$W:$W,'LC-Final List'!$Y:$Y,$A22,'LC-Final List'!$AE:$AE,"*Unpaid*",'LC-Final List'!$E:$E,D$2) -> 45771970 | E22: =SUMIFS('LC-Final List'!$W:$W,'LC-Final List'!$Y:$Y,$A22,'LC-Final List'!$AE:$AE,"*Unpaid*") -> 45771970
A23: =WORKDAY(TODAY(),20) -> 46206 | B23: =SUMIFS('LC-Final List'!$W:$W,'LC-Final List'!$Y:$Y,$A23,'LC-Final List'!$AE:$AE,"*Unpaid*",'LC-Final List'!$E:$E,B$2) -> 46944000 | C23: =SUMIFS('LC-Final List'!$W:$W,'LC-Final List'!$Y:$Y,$A23,'LC-Final List'!$AE:$AE,"*Unpaid*",'LC-Final List'!$E:$E,C$2) -> 0 | D23: =SUMIFS('LC-Final List'!$W:$W,'LC-Final List'!$Y:$Y,$A23,'LC-Final List'!$AE:$AE,"*Unpaid*",'LC-Final List'!$E:$E,D$2) -> 0 | E23: =SUMIFS('LC-Final List'!$W:$W,'LC-Final List'!$Y:$Y,$A23,'LC-Final List'!$AE:$AE,"*Unpaid*") -> 46944000
A24: =WORKDAY(TODAY(),21) -> 46209 | B24: =SUMIFS('LC-Final List'!$W:$W,'LC-Final List'!$Y:$Y,$A24,'LC-Final List'!$AE:$AE,"*Unpaid*",'LC-Final List'!$E:$E,B$2) -> 26155411 | C24: =SUMIFS('LC-Final List'!$W:$W,'LC-Final List'!$Y:$Y,$A24,'LC-Final List'!$AE:$AE,"*Unpaid*",'LC-Final List'!$E:$E,C$2) -> 0 | D24: =SUMIFS('LC-Final List'!$W:$W,'LC-Final List'!$Y:$Y,$A24,'LC-Final List'!$AE:$AE,"*Unpaid*",'LC-Final List'!$E:$E,D$2) -> 0 | E24: =SUMIFS('LC-Final List'!$W:$W,'LC-Final List'!$Y:$Y,$A24,'LC-Final List'!$AE:$AE,"*Unpaid*") -> 26155411
A25: =WORKDAY(TODAY(),22) -> 46210 | B25: =SUMIFS('LC-Final List'!$W:$W,'LC-Final List'!$Y:$Y,$A25,'LC-Final List'!$AE:$AE,"*Unpaid*",'LC-Final List'!$E:$E,B$2) -> 46944000 | C25: =SUMIFS('LC-Final List'!$W:$W,'LC-Final List'!$Y:$Y,$A25,'LC-Final List'!$AE:$AE,"*Unpaid*",'LC-Final List'!$E:$E,C$2) -> 0 | D25: =SUMIFS('LC-Final List'!$W:$W,'LC-Final List'!$Y:$Y,$A25,'LC-Final List'!$AE:$AE,"*Unpaid*",'LC-Final List'!$E:$E,D$2) -> 0 | E25: =SUMIFS('LC-Final List'!$W:$W,'LC-Final List'!$Y:$Y,$A25,'LC-Final List'!$AE:$AE,"*Unpaid*") -> 46944000
A26: =WORKDAY(TODAY(),23) -> 46211 | B26: =SUMIFS('LC-Final List'!$W:$W,'LC-Final List'!$Y:$Y,$A26,'LC-Final List'!$AE:$AE,"*Unpaid*",'LC-Final List'!$E:$E,B$2) -> 71927381 | C26: =SUMIFS('LC-Final List'!$W:$W,'LC-Final List'!$Y:$Y,$A26,'LC-Final List'!$AE:$AE,"*Unpaid*",'LC-Final List'!$E:$E,C$2) -> 0 | D26: =SUMIFS('LC-Final List'!$W:$W,'LC-Final List'!$Y:$Y,$A26,'LC-Final List'!$AE:$AE,"*Unpaid*",'LC-Final List'!$E:$E,D$2) -> 0 | E26: =SUMIFS('LC-Final List'!$W:$W,'LC-Final List'!$Y:$Y,$A26,'LC-Final List'!$AE:$AE,"*Unpaid*") -> 71927381
A27: =WORKDAY(TODAY(),24) -> 46212 | B27: =SUMIFS('LC-Final List'!$W:$W,'LC-Final List'!$Y:$Y,$A27,'LC-Final List'!$AE:$AE,"*Unpaid*",'LC-Final List'!$E:$E,B$2) -> 0 | C27: =SUMIFS('LC-Final List'!$W:$W,'LC-Final List'!$Y:$Y,$A27,'LC-Final List'!$AE:$AE,"*Unpaid*",'LC-Final List'!$E:$E,C$2) -> 0 | D27: =SUMIFS('LC-Final List'!$W:$W,'LC-Final List'!$Y:$Y,$A27,'LC-Final List'!$AE:$AE,"*Unpaid*",'LC-Final List'!$E:$E,D$2) -> 0 | E27: =SUMIFS('LC-Final List'!$W:$W,'LC-Final List'!$Y:$Y,$A27,'LC-Final List'!$AE:$AE,"*Unpaid*") -> 0
A28: =WORKDAY(TODAY(),25) -> 46213 | B28: =SUMIFS('LC-Final List'!$W:$W,'LC-Final List'!$Y:$Y,$A28,'LC-Final List'!$AE:$AE,"*Unpaid*",'LC-Final List'!$E:$E,B$2) -> 0 | C28: =SUMIFS('LC-Final List'!$W:$W,'LC-Final List'!$Y:$Y,$A28,'LC-Final List'!$AE:$AE,"*Unpaid*",'LC-Final List'!$E:$E,C$2) -> 0 | D28: =SUMIFS('LC-Final List'!$W:$W,'LC-Final List'!$Y:$Y,$A28,'LC-Final List'!$AE:$AE,"*Unpaid*",'LC-Final List'!$E:$E,D$2) -> 0 | E28: =SUMIFS('LC-Final List'!$W:$W,'LC-Final List'!$Y:$Y,$A28,'LC-Final List'!$AE:$AE,"*Unpaid*") -> 0
A29: =WORKDAY(TODAY(),26) -> 46216 | B29: =SUMIFS('LC-Final List'!$W:$W,'LC-Final List'!$Y:$Y,$A29,'LC-Final List'!$AE:$AE,"*Unpaid*",'LC-Final List'!$E:$E,B$2) -> 0 | C29: =SUMIFS('LC-Final List'!$W:$W,'LC-Final List'!$Y:$Y,$A29,'LC-Final List'!$AE:$AE,"*Unpaid*",'LC-Final List'!$E:$E,C$2) -> 5431296 | D29: =SUMIFS('LC-Final List'!$W:$W,'LC-Final List'!$Y:$Y,$A29,'LC-Final List'!$AE:$AE,"*Unpaid*",'LC-Final List'!$E:$E,D$2) -> 0 | E29: =SUMIFS('LC-Final List'!$W:$W,'LC-Final List'!$Y:$Y,$A29,'LC-Final List'!$AE:$AE,"*Unpaid*") -> 5431296
A30: =WORKDAY(TODAY(),27) -> 46217 | B30: =SUMIFS('LC-Final List'!$W:$W,'LC-Final List'!$Y:$Y,$A30,'LC-Final List'!$AE:$AE,"*Unpaid*",'LC-Final List'!$E:$E,B$2) -> 57673728 | C30: =SUMIFS('LC-Final List'!$W:$W,'LC-Final List'!$Y:$Y,$A30,'LC-Final List'!$AE:$AE,"*Unpaid*",'LC-Final List'!$E:$E,C$2) -> 0 | D30: =SUMIFS('LC-Final List'!$W:$W,'LC-Final List'!$Y:$Y,$A30,'LC-Final List'!$AE:$AE,"*Unpaid*",'LC-Final List'!$E:$E,D$2) -> 0 | E30: =SUMIFS('LC-Final List'!$W:$W,'LC-Final List'!$Y:$Y,$A30,'LC-Final List'!$AE:$AE,"*Unpaid*") -> 57673728
A31: =WORKDAY(TODAY(),28) -> 46218 | B31: =SUMIFS('LC-Final List'!$W:$W,'LC-Final List'!$Y:$Y,$A31,'LC-Final List'!$AE:$AE,"*Unpaid*",'LC-Final List'!$E:$E,B$2) -> 53705760 | C31: =SUMIFS('LC-Final List'!$W:$W,'LC-Final List'!$Y:$Y,$A31,'LC-Final List'!$AE:$AE,"*Unpaid*",'LC-Final List'!$E:$E,C$2) -> 0 | D31: =SUMIFS('LC-Final List'!$W:$W,'LC-Final List'!$Y:$Y,$A31,'LC-Final List'!$AE:$AE,"*Unpaid*",'LC-Final List'!$E:$E,D$2) -> 0 | E31: =SUMIFS('LC-Final List'!$W:$W,'LC-Final List'!$Y:$Y,$A31,'LC-Final List'!$AE:$AE,"*Unpaid*") -> 53705760
A32: =WORKDAY(TODAY(),29) -> 46219 | B32: =SUMIFS('LC-Final List'!$W:$W,'LC-Final List'!$Y:$Y,$A32,'LC-Final List'!$AE:$AE,"*Unpaid*",'LC-Final List'!$E:$E,B$2) -> 0 | C32: =SUMIFS('LC-Final List'!$W:$W,'LC-Final List'!$Y:$Y,$A32,'LC-Final List'!$AE:$AE,"*Unpaid*",'LC-Final List'!$E:$E,C$2) -> 0 | D32: =SUMIFS('LC-Final List'!$W:$W,'LC-Final List'!$Y:$Y,$A32,'LC-Final List'!$AE:$AE,"*Unpaid*",'LC-Final List'!$E:$E,D$2) -> 0 | E32: =SUMIFS('LC-Final List'!$W:$W,'LC-Final List'!$Y:$Y,$A32,'LC-Final List'!$AE:$AE,"*Unpaid*") -> 0
A33: =WORKDAY(TODAY(),30) -> 46220 | B33: =SUMIFS('LC-Final List'!$W:$W,'LC-Final List'!$Y:$Y,$A33,'LC-Final List'!$AE:$AE,"*Unpaid*",'LC-Final List'!$E:$E,B$2) -> 0 | C33: =SUMIFS('LC-Final List'!$W:$W,'LC-Final List'!$Y:$Y,$A33,'LC-Final List'!$AE:$AE,"*Unpaid*",'LC-Final List'!$E:$E,C$2) -> 0 | D33: =SUMIFS('LC-Final List'!$W:$W,'LC-Final List'!$Y:$Y,$A33,'LC-Final List'!$AE:$AE,"*Unpaid*",'LC-Final List'!$E:$E,D$2) -> 0 | E33: =SUMIFS('LC-Final List'!$W:$W,'LC-Final List'!$Y:$Y,$A33,'LC-Final List'!$AE:$AE,"*Unpaid*") -> 0
A34: =WORKDAY(TODAY(),31) -> 46223 | B34: =SUMIFS('LC-Final List'!$W:$W,'LC-Final List'!$Y:$Y,$A34,'LC-Final List'!$AE:$AE,"*Unpaid*",'LC-Final List'!$E:$E,B$2) -> 0 | C34: =SUMIFS('LC-Final List'!$W:$W,'LC-Final List'!$Y:$Y,$A34,'LC-Final List'!$AE:$AE,"*Unpaid*",'LC-Final List'!$E:$E,C$2) -> 0 | D34: =SUMIFS('LC-Final List'!$W:$W,'LC-Final List'!$Y:$Y,$A34,'LC-Final List'!$AE:$AE,"*Unpaid*",'LC-Final List'!$E:$E,D$2) -> 0 | E34: =SUMIFS('LC-Final List'!$W:$W,'LC-Final List'!$Y:$Y,$A34,'LC-Final List'!$AE:$AE,"*Unpaid*") -> 0
A36: TOTAL OUTSTANDING | E36: =SUM(E3:E22) -> 3.0841039e+09 | G36: TOTAL OUTSTANDING | H36: =SUM(H3:H35) -> 4417019976

Sheet C_Limit Available_Planning
A1: LC Limit Available
A3: SBLC Status | B3: (Multiple Items)
A5: Sum of LC Limit Available
B6: CANCELLED | D6: NO | F6: YES | I6: SOFT COPY | K6: Grand Total
A7: Row Labels | B7: IDBI | C7: SBI | D7: IDBI | E7: SBI | F7: IDBI | G7: SBI | H7: BOI | I7: IDBI | J7: SBI
A8: 46173 | B8: 6626521 | K8: 6626521
A9: 46176 | G9: 672489216 | K9: 672489216
A10: 46177 | G10: 3.0758289e+08 | K10: 3.0758289e+08
A11: 46178 | G11: 1.3027923e+08 | K11: 1.3027923e+08
A12: 46179 | F12: 8697848.7 | H12: 40095952 | K12: 48793801
A13: 46184 | G13: 4.8433801e+08 | H13: 72808013 | K13: 5.5714602e+08
A14: 46186 | G14: 2.4195297e+08 | K14: 2.4195297e+08
A15: 46187 | G15: 5.509516e+08 | H15: 169992000 | K15: 7.209436e+08
A16: 46190 | G16: 5.9444844e+08 | H16: 232502400 | K16: 8.2695084e+08
A17: 46191 | G17: 76898304 | K17: 76898304
A18: 46192 | C18: 3.3370871e+08 | G18: 1.304605e+08 | K18: 4.641692e+08
A19: 46194 | B19: 15587582 | K19: 15587582
A20: 46197 | B20: 825702.72 | F20: 3.5825918e+08 | G20: 182793600 | K20: 541878480
A21: 46198 | J21: 6344064 | K21: 6344064
A22: 46200 | H22: 52310822 | K22: 52310822
A23: 46204 | G23: 105580800 | K23: 105580800
A24: 46207 | H24: 45771970 | K24: 45771970
A25: 46212 | G25: 93888000 | K25: 93888000
A26: 46213 | J26: 98082794 | K26: 98082794
A27: 46216 | I27: 5431296 | K27: 5431296
A28: 46219 | E28: 57673728 | K28: 57673728
A29: 46220 | E29: 53705760 | K29: 53705760
A30: 46224 | I30: 49147085 | K30: 49147085
A31: 46235 | E31: 106310400 | K31: 106310400
A32: 46250 | D32: 22579200 | K32: 22579200
A33: 46255 | D33: 6420480 | K33: 6420480
A34: (blank) | C34: 0 | E34: 0 | G34: 0 | K34: 0
A35: Grand Total | B35: 23039806 | C35: 3.3370871e+08 | D35: 28999680 | E35: 217689888 | F35: 366957026 | G35: 3.5716636e+09 | H35: 6.1348116e+08 | I35: 54578381 | J35: 1.0442686e+08 | K35: 5.3145451e+09

Sheet LC-Summary
A1: Sr. No. | B1: Particular | C1: Amount | E1: Details | F1: Existing Limit | G1: TRANSFER FROM CC TO LC limit | H1: Interchangeability Limit to SBLC | I1: Total Current NFB limit | J1: Outstanding | K1: In Process | L1: LC request received and not process | N1: LC Limit Available | O1: BG Limit Available
E2: IDBI -LC | F2: =1500000000 -> 1500000000 | G2: =160000000+7000000-140000000 -> 27000000 | H2: 822500000 | I2: =F2+G2 -> 1527000000 | J2: =$C$5+H2 -> 1.2651629e+09 | N2: =I2-J2 -> 2.6183706e+08
A3: 2 | B3: LC Cancelled | C3: =SUMIF('LC-Final List'!$AD$2:$AD$222,B3,'LC-Final List'!$W$2:$W$222) -> 36772620 | E3: BOI -LC | F3: =1570000000 -> 1570000000 | G3: 0 | H3: 820000000 | I3: =F3+G3 -> 1570000000 | J3: =$C$6+H3 -> 1.3933852e+09 | K3: 0 | N3: =I3-J3-K3 -> 1.766148e+08
A4: 3 | B4: BOE Received and Paid | C4: =SUMIFS('LC-Final List'!$W:$W,'LC-Final List'!$AD:$AD,B4) -> 7.9891687e+09 | E4: SBI -LC | F4: 7840000000 | G4: 0 | H4: 1810000000 | I4: =F4-H4 -> 6030000000 | J4: =$C$8+5000000 -> 3.961815e+09 | K4: 45000000 | L4: ='LC BG in Process'!H10-'LC-Summary'!K2-'LC-Summary'!K3-'LC-Summary'!K4 -> 4.1646475e+08 | N4: =I4-J4-K4 -> 2.023185e+09
B5: IDBI | C5: =SUMIFS('LC-Final List'!$W:$W,'LC-Final List'!$AH:$AH,"Open",'LC-Final List'!$E:$E,'LC-Summary'!B5) -> 4.4266294e+08 | E5: SBI -CAPEX LC | J5: =$C$7 -> 1.3209023e+08
B6: BOI | C6: =SUMIFS('LC-Final List'!$W:$W,'LC-Final List'!$AH:$AH,"Open",'LC-Final List'!$E:$E,'LC-Summary'!B6) -> 5.733852e+08 | E6: SBI -LC 110% | J6: 0
A7: Capex | B7: 1 | C7: =SUMIFS('LC-Final List'!$M:$M,'LC-Final List'!$F:$F,B7,'LC-Final List'!$AH:$AH,"Open") -> 1.3209023e+08
A8: 0.1 | B8: SBI | C8: =SUMIFS('LC-Final List'!$M:$M,'LC-Final List'!$AH:$AH,"Open",'LC-Final List'!$E:$E,'LC-Summary'!B8,'LC-Final List'!$F:$F,A8) -> 3.956815e+09
B9: Total LC Outstanding | C9: =C8+C5+C6 -> 4.9728631e+09 | E9: SBI-BG 10% | F9: 4500000000 | H9: 0 | I9: =F9-H9 -> 4500000000 | J9: =SUMIF('Bank Guarantee'!$B$2:$B$32,'LC-Summary'!E9,'Bank Guarantee'!$F$2:$F$32) -> 1801696196 | N9: =I9-J9-K9 -> 2698303804
A10: 4 | B10: Part/Full BOE received & Unpaid | C10: =SUMIFS('LC-Final List'!$W:$W,'LC-Final List'!$AD:$AD,'LC-Summary'!B10,'LC-Final List'!$AE:$AE,"Unpaid") -> 3.3306531e+09 | E10: IDBI -BG | F10: 630000000 | H10: 0 | I10: =F10-H10 -> 630000000 | J10: =SUMIF('Bank Guarantee'!$B$2:$B$24,'LC-Summary'!E10,'Bank Guarantee'!$F$2:$F$24) -> 157812020 | K10: 0 | N10: =I10-J10-K10 -> 472187980
A11: 5 | B11: BOE not received | C11: =SUMIF('LC-Final List'!$AD$2:$AD$222,B11,'LC-Final List'!$W$2:$W$222) -> 1.1769724e+09 | E11: BOI-BG | F11: 770000000 | H11: 0 | I11: =F11-H11 -> 770000000 | J11: 0 | K11: 0 | N11: =I11-J11-K11 -> 770000000
A12: Bill Paid | B12: Part/Full BOE received & Unpaid | C12: =SUMIFS('LC-Final List'!$W:$W,'LC-Final List'!$AD:$AD,'LC-Summary'!B12,'LC-Final List'!$AE:$AE,"paid") -> 4.6523767e+08 | E12: SBI BG 100% | F12: 0 | H12: 0 | I12: =F12-H12 -> 0 | J12: =SUMIF('Bank Guarantee'!$B$2:$B$33,'LC-Summary'!E12,'Bank Guarantee'!$F$2:$F$33) -> 94783120 | K12: 0
E13: TOTAL | F13: =SUM(F2:F11) -> 16810000000 | H13: =SUM(H2:H11) -> 3452500000 | I13: =I2+I10+I4+I9+I3+I11 -> 15027000000 | J13: =J2+J10+J4+J9+J3+J11 -> 8.5798713e+09 | K13: =K4+K9+K3+K11+K2 -> 45000000 | N13: =SUM(N2:N12) -> 6.4021287e+09 | O13: =SUM(O2:O12) -> 0
A16: SBLC OUTSTANDING
A18: Month | C18: TOTAL SBLC AMT | D18: Paid till Date | E18: O/s as on date
A19: 46113 | C19: =SUMIF(SBLC!$S$2:$S$27,'LC-Summary'!A19,SBLC!$Q$2:$Q$27) -> 135016110 | D19: =SUMIFS(SBLC!Q:Q,SBLC!T:T,"Paid",SBLC!S:S,'LC-Summary'!A19) -> 135016110 | E19: =C19-D19 -> 0
A20: 46204 | C20: =SUMIF(SBLC!$S$2:$S$70,'LC-Summary'!A20,SBLC!$X$2:$X$70) -> 1.7340395e+09 | D20: =SUMIFS(SBLC!X:X,SBLC!T:T,"Paid",SBLC!S:S,'LC-Summary'!A20) -> 0 | E20: =C20-D20 -> 1.7340395e+09
A21: 46235 | C21: =SUMIF(SBLC!$S$2:$S$70,'LC-Summary'!A21,SBLC!$X$2:$X$70) -> 2.6826307e+08 | D21: =SUMIFS(SBLC!X:X,SBLC!T:T,"Paid",SBLC!S:S,'LC-Summary'!A21) -> 0 | E21: =C21-D21 -> 2.6826307e+08
A22: 46266 | C22: =SUMIF(SBLC!$S$2:$S$70,'LC-Summary'!A22,SBLC!$X$2:$X$70) -> 1.22739e+08 | D22: =SUMIFS(SBLC!X:X,SBLC!T:T,"Paid",SBLC!S:S,'LC-Summary'!A22) -> 0 | E22: =C22-D22 -> 1.22739e+08
A23: 46296 | C23: =SUMIF(SBLC!$S$2:$S$70,'LC-Summary'!A23,SBLC!$X$2:$X$70) -> 0 | D23: =SUMIFS(SBLC!X:X,SBLC!T:T,"Paid",SBLC!S:S,'LC-Summary'!A23) -> 0 | E23: =C23-D23 -> 0
A24: 46327 | C24: =SUMIF(SBLC!$S$2:$S$70,'LC-Summary'!A24,SBLC!$X$2:$X$70) -> 6.4625993e+08 | D24: =SUMIFS(SBLC!X:X,SBLC!T:T,"Paid",SBLC!S:S,'LC-Summary'!A24) -> 0 | E24: =C24-D24 -> 6.4625993e+08
A26: Total | C26: =SUM(C19:C25) -> 2.9063176e+09 | D26: =SUM(D19:D25) -> 135016110 | E26: =SUM(E19:E25) -> 2.7713015e+09

Sheet DAILY UPDATE SHEET
A1: 📊 SUMMARY – LC & BILL POSITION
A3: 1️⃣ Total LC Exposure and Available Limit Snapshot | G3: 1️⃣ (a) Margin Wise LC Bifurcation - Total LC Exposure
A5: Category | B5: SBI | C5: IDBI | D5: BOI | E5: Total | G5: Margin % | H5: SBI | I5: IDBI | J5: BOI | K5: Total
A6: A. BANK LIMITS (10% Margin) | G6: 0.1 | H6: =B14 -> 4.0026525e+09 | I6: =C14 -> 4.4266294e+08 | J6: =D14 -> 5.733852e+08 | K6: =SUM(H6:J6) -> 5.0187006e+09
A7: Existing Limit | B7: 7840000000 | C7: 1500000000 | D7: 1570000000 | E7: =B7+C7+D7 -> 10910000000 | G7: 1 | H7: =B26 -> 1.3209023e+08 | I7: =C26 -> 0 | J7: =D26 -> 0 | K7: =SUM(H7:J7) -> 1.3209023e+08
A8: Interchangability Limit | B8: 1810000000 | C8: =160000000+7000000-140000000 -> 27000000 | E8: =B8+C8+D8 -> 1837000000 | G8: 1.1 | H8: =B33 -> 0 | I8: =C33 -> 0 | J8: =D33 -> 0 | K8: =SUM(H8:J8) -> 0
A9: Total Current NFB limit (A) | B9: =B7-B8 -> 6030000000 | C9: =C7+C8 -> 1527000000 | D9: =D7+D8 -> 1570000000 | E9: =SUM(B9:D9) -> 9127000000 | G9: Total | H9: =SUM(H6:H8) -> 4.1347427e+09 | I9: =SUM(I6:I8) -> 4.4266294e+08 | J9: =SUM(J6:J8) -> 5.733852e+08 | K9: =SUM(K6:K8) -> 5.1507909e+09
A11: B. UTILIZATION
A12: LC Outstanding | B12: =SUMIFS('LC-Final List'!$M:$M,'LC-Final List'!$AH:$AH,"Open",'LC-Final List'!$E:$E,'DAILY UPDATE SHEET'!B$5,'LC-Final List'!$F:$F,"10%") -> 3.956815e+09 | C12: =SUMIFS('LC-Final List'!$W:$W,'LC-Final List'!$AH:$AH,"Open",'LC-Final List'!$E:$E,'DAILY UPDATE SHEET'!C$5,'LC-Final List'!$F:$F,"10%") -> 4.4266294e+08 | D12: =SUMIFS('LC-Final List'!$W:$W,'LC-Final List'!$AH:$AH,"Open",'LC-Final List'!$E:$E,'DAILY UPDATE SHEET'!D$5,'LC-Final List'!$F:$F,"10%") -> 5.733852e+08 | E12: =B12+C12+D12 -> 4.9728631e+09 | G12: 1️⃣ (b) 10% Margin - BOE Position (Open LCs)
A13: LC in Process | B13: =SUMIFS('LC BG in Process'!$H:$H,'LC BG in Process'!$K:$K,"DOC SUBMITTED TO BANK",'LC BG in Process'!$A:$A,"LC",'LC BG in Process'!$C:$C,"10%",'LC BG in Process'!$B:$B,'DAILY UPDATE SHEET'!B$5) -> 45837500 | C13: =SUMIFS('LC BG in Process'!$H:$H,'LC BG in Process'!$K:$K,"DOC SUBMITTED TO BANK",'LC BG in Process'!$A:$A,"LC",'LC BG in Process'!$C:$C,"10%",'LC BG in Process'!$B:$B,'DAILY UPDATE SHEET'!C$5) -> 0 | D13: =SUMIFS('LC BG in Process'!$H:$H,'LC BG in Process'!$K:$K,"DOC SUBMITTED TO BANK",'LC BG in Process'!$A:$A,"LC",'LC BG in Process'!$C:$C,"10%",'LC BG in Process'!$B:$B,'DAILY UPDATE SHEET'!D$5) -> 0 | E13: =B13+C13+D13 -> 45837500
A14: Total LC Exposure (B) | B14: =SUM(B12:B13) -> 4.0026525e+09 | C14: =SUM(C12:C13) -> 4.4266294e+08 | D14: =SUM(D12:D13) -> 5.733852e+08 | E14: =SUM(E12:E13) -> 5.0187006e+09 | G14: Bill Status | H14: =H5 -> SBI | I14: =I5 -> IDBI | J14: =J5 -> BOI | K14: Total
G15: BOE Received and Paid | H15: =SUMIFS('LC-Final List'!$W:$W,'LC-Final List'!$AH:$AH,"Open",'LC-Final List'!$AF:$AF,"Received",'LC-Final List'!$AE:$AE,"Paid",'LC-Final List'!$F:$F,"10%",'LC-Final List'!$E:$E,$H$14) -> 4.6523767e+08 | I15: =SUMIFS('LC-Final List'!$W:$W,'LC-Final List'!$AH:$AH,"Open",'LC-Final List'!$AF:$AF,"Received",'LC-Final List'!$AE:$AE,"Paid",'LC-Final List'!$F:$F,"10%",'LC-Final List'!$E:$E,$I$14) -> 0 | J15: =SUMIFS('LC-Final List'!$W:$W,'LC-Final List'!$AH:$AH,"Open",'LC-Final List'!$AF:$AF,"Received",'LC-Final List'!$AE:$AE,"Paid",'LC-Final List'!$F:$F,"10%",'LC-Final List'!$E:$E,$J$14) -> 0 | K15: =SUM(H15:J15) -> 4.6523767e+08
A16: C. SBLC UTILIZATION | G16: BOE Received and Unpaid | H16: =SUMIFS('LC-Final List'!$W:$W,'LC-Final List'!$AH:$AH,"Open",'LC-Final List'!$AF:$AF,"Received",'LC-Final List'!$AE:$AE,"Unpaid",'LC-Final List'!$F:$F,"10%",'LC-Final List'!$E:$E,$H$14) -> 2.3444303e+09 | I16: =SUMIFS('LC-Final List'!$W:$W,'LC-Final List'!$AH:$AH,"Open",'LC-Final List'!$AF:$AF,"Received",'LC-Final List'!$AE:$AE,"Unpaid",'LC-Final List'!$F:$F,"10%",'LC-Final List'!$E:$E,$I$14) -> 4.1283756e+08 | J16: =SUMIFS('LC-Final List'!$W:$W,'LC-Final List'!$AH:$AH,"Open",'LC-Final List'!$AF:$AF,"Received",'LC-Final List'!$AE:$AE,"Unpaid",'LC-Final List'!$F:$F,"10%",'LC-Final List'!$E:$E,$J$14) -> 5.733852e+08 | K16: =SUM(H16:J16) -> 3.3306531e+09
A17: SBLC Outstanding | B17: =SUMIFS(SBLC!$X:$X,SBLC!$T:$T,"Unpaid",SBLC!$B:$B,'DAILY UPDATE SHEET'!B$5) -> 1.1375264e+09 | C17: =SUMIFS(SBLC!$X:$X,SBLC!$T:$T,"Unpaid",SBLC!$B:$B,'DAILY UPDATE SHEET'!C$5) -> 8.2202324e+08 | D17: =SUMIFS(SBLC!$X:$X,SBLC!$T:$T,"Unpaid",SBLC!$B:$B,'DAILY UPDATE SHEET'!D$5) -> 8.205892e+08 | E17: =SUM(B17:D17) -> 2.7801389e+09 | G17: BOE Not Received | H17: =SUMIFS('LC-Final List'!$W:$W,'LC-Final List'!$AH:$AH,"Open",'LC-Final List'!$AF:$AF,"Not Received",'LC-Final List'!$AE:$AE,"Unpaid",'LC-Final List'!$F:$F,"10%",'LC-Final List'!$E:$E,$H$14) -> 1.0573672e+09 | I17: =SUMIFS('LC-Final List'!$W:$W,'LC-Final List'!$AH:$AH,"Open",'LC-Final List'!$AF:$AF,"Not Received",'LC-Final List'!$AE:$AE,"Unpaid",'LC-Final List'!$F:$F,"10%",'LC-Final List'!$E:$E,$I$14) -> 28999680 | J17: =SUMIFS('LC-Final List'!$W:$W,'LC-Final List'!$AH:$AH,"Open",'LC-Final List'!$AF:$AF,"Not Received",'LC-Final List'!$AE:$AE,"Unpaid",'LC-Final List'!$F:$F,"10%",'LC-Final List'!$E:$E,$J$14) -> 0 | K17: =SUM(H17:J17) -> 1.0863669e+09
A18: Total SBLC Exposure (C) | B18: =SUM(B16:B17) -> 1.1375264e+09 | C18: =SUM(C16:C17) -> 8.2202324e+08 | D18: =SUM(D16:D17) -> 8.205892e+08 | E18: =SUM(E16:E17) -> 2.7801389e+09 | G18: Cancelled | H18: =SUMIFS('LC-Final List'!$W:$W,'LC-Final List'!$AH:$AH,"Open",'LC-Final List'!$AF:$AF,"Cancelled",'LC-Final List'!$F:$F,"10%",'LC-Final List'!$E:$E,$H$14) -> 89779774 | I18: =SUMIFS('LC-Final List'!$W:$W,'LC-Final List'!$AH:$AH,"Open",'LC-Final List'!$AF:$AF,"Cancelled",'LC-Final List'!$F:$F,"10%",'LC-Final List'!$E:$E,$I$14) -> 825702.72 | J18: =SUMIFS('LC-Final List'!$W:$W,'LC-Final List'!$AH:$AH,"Open",'LC-Final List'!$AF:$AF,"Cancelled",'LC-Final List'!$F:$F,"10%",'LC-Final List'!$E:$E,$J$14) -> 0 | K18: =SUM(H18:J18) -> 90605477
G19: Total | H19: =SUM(H15:H18) -> 3.956815e+09 | I19: =SUM(I15:I18) -> 4.4266294e+08 | J19: =SUM(J15:J18) -> 5.733852e+08 | K19: =SUM(K15:K18) -> 4.9728631e+09
A20: C. HEADROOM
A21: Available Balance (D) = (A - B-C) | B21: =B9-B14 -> 2.0273475e+09 | C21: =C9-C14-C18 -> 2.6231382e+08 | D21: =D9-D14-D18 -> 1.760256e+08 | E21: =B21+C21+D21 -> 2.4656869e+09 | G21: Reconcilation | H21: =H19-B12 -> -2.3039999 | I21: =I19-C12 -> 0 | J21: =J19-D12 -> 0 | K21: =K19-E12 -> -2.3039999
A22: AVAILABLE SBLC LIMIT IN SBI | B22: =B8-B18 -> 6.7247356e+08 | E22: =B22+C22+D22 -> 6.7247356e+08
A23: LC Limit Utilization (%) | B23: =B14/B9 -> 0.6637898 | C23: =(C14+C18)/C9 -> 0.82821623 | D23: =(D14+D18)/D9 -> 0.88788178
A24: SBLC Limit Utilization | B24: =B17/B8 -> 0.62846765 | G24: 1️⃣ ( C ) Outstanding Payables: Currency Exposure & Hedge Status
A26: Total 100% Margin LC Exposure | B26: =SUM(B27:B28) -> 1.3209023e+08 | C26: =SUM(C27:C28) -> 0 | D26: =SUM(D27:D28) -> 0 | E26: =SUM(B26:D26) -> 1.3209023e+08 | G26: Currency Exposure (FX Risk) | H26: TOTAL Unpaid Bill | I26: HEDGED | J26: UNHEDGED
A27: 100% LC Outstanding | B27: =SUMIFS('LC-Final List'!$M:$M,'LC-Final List'!$AH:$AH,"Open",'LC-Final List'!$E:$E,'DAILY UPDATE SHEET'!B$5,'LC-Final List'!$F:$F,"100%") -> 1.3209023e+08 | C27: =SUMIFS('LC-Final List'!$M:$M,'LC-Final List'!$AH:$AH,"Open",'LC-Final List'!$E:$E,'DAILY UPDATE SHEET'!C$5,'LC-Final List'!$F:$F,"100%") -> 0 | D27: =SUMIFS('LC-Final List'!$M:$M,'LC-Final List'!$AH:$AH,"Open",'LC-Final List'!$E:$E,'DAILY UPDATE SHEET'!D$5,'LC-Final List'!$F:$F,"100%") -> 0 | E27: =SUM(B27:D27) -> 1.3209023e+08 | G27: USD- RAW MATERIAL | H27: =SUMIFS('LC-Final List'!$U:$U,'LC-Final List'!$AH:$AH,"Open",'LC-Final List'!$AE:$AE,"Unpaid",'LC-Final List'!$F:$F,"10%",'LC-Final List'!$H:$H,"USD") -> 46010625 | J27: =H27-I27 -> 46010625
A28: 100% in Process | B28: =SUMIFS('LC BG in Process'!$H:$H,'LC BG in Process'!$K:$K,"DOC SUBMITTED TO BANK",'LC BG in Process'!$A:$A,"LC",'LC BG in Process'!$C:$C,"100%",'LC BG in Process'!$B:$B,'DAILY UPDATE SHEET'!B$5) -> 0 | C28: =SUMIFS('LC BG in Process'!$H:$H,'LC BG in Process'!$K:$K,"DOC SUBMITTED TO BANK",'LC BG in Process'!$A:$A,"LC",'LC BG in Process'!$C:$C,"100%",'LC BG in Process'!$B:$B,'DAILY UPDATE SHEET'!C$5) -> 0 | D28: =SUMIFS('LC BG in Process'!$H:$H,'LC BG in Process'!$K:$K,"DOC SUBMITTED TO BANK",'LC BG in Process'!$A:$A,"LC",'LC BG in Process'!$C:$C,"100%",'LC BG in Process'!$B:$B,'DAILY UPDATE SHEET'!D$5) -> 0 | E28: =SUM(B28:D28) -> 0 | G28: USD-CAPEX | H28: =SUMIFS('LC-Final List'!$U:$U,'LC-Final List'!$AH:$AH,"Open",'LC-Final List'!$AE:$AE,"Unpaid",'LC-Final List'!$F:$F,"100%",'LC-Final List'!$H:$H,"USD") -> 1345674 | I28: 1345674 | J28: =H28-I28 -> 0
G29: EUR-CAPEX | H29: =SUMIFS('LC-Final List'!$U:$U,'LC-Final List'!$AH:$AH,"Open",'LC-Final List'!$AE:$AE,"Unpaid",'LC-Final List'!$F:$F,"100%",'LC-Final List'!$H:$H,"EUR") -> 30000 | I29: 30000 | J29: =H29-I29 -> 0
A30: Total 110% Margin LC Exposure | B30: =SUM(B31:B32) -> 0 | C30: =SUM(C31:C32) -> 0 | D30: =SUM(D31:D32) -> 0 | E30: =SUM(B30:D30) -> 0 | G30: Total | H30: 80416960 | I30: 1375674 | J30: 79041286
A31: 110% LC Outstanding | B31: =SUMIFS('LC-Final List'!$M:$M,'LC-Final List'!$AH:$AH,"Open",'LC-Final List'!$E:$E,'DAILY UPDATE SHEET'!B$5,'LC-Final List'!$F:$F,"110%") -> 0 | C31: =SUMIFS('LC-Final List'!$M:$M,'LC-Final List'!$AH:$AH,"Open",'LC-Final List'!$E:$E,'DAILY UPDATE SHEET'!C$5,'LC-Final List'!$F:$F,"110%") -> 0 | D31: =SUMIFS('LC-Final List'!$M:$M,'LC-Final List'!$AH:$AH,"Open",'LC-Final List'!$E:$E,'DAILY UPDATE SHEET'!D$5,'LC-Final List'!$F:$F,"110%") -> 0 | E31: =SUM(B31:D31) -> 0
A32: 110% in Process | B32: =SUMIFS('LC BG in Process'!$H:$H,'LC BG in Process'!$K:$K,"DOC SUBMITTED TO BANK",'LC BG in Process'!$A:$A,"LC",'LC BG in Process'!$C:$C,"110%",'LC BG in Process'!$B:$B,'DAILY UPDATE SHEET'!B$5) -> 0 | C32: =SUMIFS('LC BG in Process'!$H:$H,'LC BG in Process'!$K:$K,"DOC SUBMITTED TO BANK",'LC BG in Process'!$A:$A,"LC",'LC BG in Process'!$C:$C,"110%",'LC BG in Process'!$B:$B,'DAILY UPDATE SHEET'!C$5) -> 0 | D32: =SUMIFS('LC BG in Process'!$H:$H,'LC BG in Process'!$K:$K,"DOC SUBMITTED TO BANK",'LC BG in Process'!$A:$A,"LC",'LC BG in Process'!$C:$C,"110%",'LC BG in Process'!$B:$B,'DAILY UPDATE SHEET'!D$5) -> 0 | E32: =SUM(B32:D32) -> 0
A34: Daily Payment Schedule
A36: DAILY PAYMENT SCHEDULE | B36: SBI | D36: IDBI | F36: BOI | H36: PAYABLE AMOUNT (INR)
B37: LC | C37: SBLC | D37: LC | E37: SBLC | F37: LC | G37: SBLC
A38: =TODAY() -> 46178 | B38: =SUMIFS('LC-Final List'!$W:$W,'LC-Final List'!$AE:$AE,"Unpaid",'LC-Final List'!$Y:$Y,'DAILY UPDATE SHEET'!$A38,'LC-Final List'!$E:$E,'DAILY UPDATE SHEET'!B$36,'LC-Final List'!$F:$F,"10%") -> 103736160 | C38: =SUMIFS(SBLC!$X:$X,SBLC!$T:$T,"Unpaid",SBLC!$R:$R,'DAILY UPDATE SHEET'!$A38,SBLC!$B:$B,$B$36,SBLC!$H:$H,"10%") -> 0 | D38: =SUMIFS('LC-Final List'!$W:$W,'LC-Final List'!$AE:$AE,"Unpaid",'LC-Final List'!$Y:$Y,'DAILY UPDATE SHEET'!$A38,'LC-Final List'!$E:$E,'DAILY UPDATE SHEET'!D$36,'LC-Final List'!$F:$F,"10%") -> 0 | E38: =SUMIFS(SBLC!$X:$X,SBLC!$T:$T,"Unpaid",SBLC!$R:$R,'DAILY UPDATE SHEET'!$A38,SBLC!$B:$B,$D$36,SBLC!$H:$H,"10%") -> 0 | F38: =SUMIFS('LC-Final List'!$W:$W,'LC-Final List'!$AE:$AE,"Unpaid",'LC-Final List'!$Y:$Y,'DAILY UPDATE SHEET'!$A38,'LC-Final List'!$E:$E,'DAILY UPDATE SHEET'!F$36,'LC-Final List'!$F:$F,"10%") -> 0 | G38: =SUMIFS(SBLC!$X:$X,SBLC!$T:$T,"Unpaid",SBLC!$R:$R,'DAILY UPDATE SHEET'!$A38,SBLC!$B:$B,$F$36,SBLC!$H:$H,"10%") -> 0 | H38: =SUM(B38:G38) -> 103736160
A39: =A38+1 -> 46179 | B39: =SUMIFS('LC-Final List'!$W:$W,'LC-Final List'!$AE:$AE,"Unpaid",'LC-Final List'!$Y:$Y,'DAILY UPDATE SHEET'!$A39,'LC-Final List'!$E:$E,'DAILY UPDATE SHEET'!B$36,'LC-Final List'!$F:$F,"10%") -> 0 | C39: =SUMIFS(SBLC!$X:$X,SBLC!$T:$T,"Unpaid",SBLC!$R:$R,'DAILY UPDATE SHEET'!$A39,SBLC!$B:$B,$B$36,SBLC!$H:$H,"10%") -> 0 | D39: =SUMIFS('LC-Final List'!$W:$W,'LC-Final List'!$AE:$AE,"Unpaid",'LC-Final List'!$Y:$Y,'DAILY UPDATE SHEET'!$A39,'LC-Final List'!$E:$E,'DAILY UPDATE SHEET'!D$36,'LC-Final List'!$F:$F,"10%") -> 0 | E39: =SUMIFS(SBLC!$X:$X,SBLC!$T:$T,"Unpaid",SBLC!$R:$R,'DAILY UPDATE SHEET'!$A39,SBLC!$B:$B,$D$36,SBLC!$H:$H,"10%") -> 0 | F39: =SUMIFS('LC-Final List'!$W:$W,'LC-Final List'!$AE:$AE,"Unpaid",'LC-Final List'!$Y:$Y,'DAILY UPDATE SHEET'!$A39,'LC-Final List'!$E:$E,'DAILY UPDATE SHEET'!F$36,'LC-Final List'!$F:$F,"10%") -> 0 | G39: =SUMIFS(SBLC!$X:$X,SBLC!$T:$T,"Unpaid",SBLC!$R:$R,'DAILY UPDATE SHEET'!$A39,SBLC!$B:$B,$F$36,SBLC!$H:$H,"10%") -> 0 | H39: =SUM(B39:G39) -> 0
A40: =A39+1 -> 46180 | B40: =SUMIFS('LC-Final List'!$W:$W,'LC-Final List'!$AE:$AE,"Unpaid",'LC-Final List'!$Y:$Y,'DAILY UPDATE SHEET'!$A40,'LC-Final List'!$E:$E,'DAILY UPDATE SHEET'!B$36,'LC-Final List'!$F:$F,"10%") -> 0 | C40: =SUMIFS(SBLC!$X:$X,SBLC!$T:$T,"Unpaid",SBLC!$R:$R,'DAILY UPDATE SHEET'!$A40,SBLC!$B:$B,$B$36,SBLC!$H:$H,"10%") -> 0 | D40: =SUMIFS('LC-Final List'!$W:$W,'LC-Final List'!$AE:$AE,"Unpaid",'LC-Final List'!$Y:$Y,'DAILY UPDATE SHEET'!$A40,'LC-Final List'!$E:$E,'DAILY UPDATE SHEET'!D$36,'LC-Final List'!$F:$F,"10%") -> 0 | E40: =SUMIFS(SBLC!$X:$X,SBLC!$T:$T,"Unpaid",SBLC!$R:$R,'DAILY UPDATE SHEET'!$A40,SBLC!$B:$B,$D$36,SBLC!$H:$H,"10%") -> 0 | F40: =SUMIFS('LC-Final List'!$W:$W,'LC-Final List'!$AE:$AE,"Unpaid",'LC-Final List'!$Y:$Y,'DAILY UPDATE SHEET'!$A40,'LC-Final List'!$E:$E,'DAILY UPDATE SHEET'!F$36,'LC-Final List'!$F:$F,"10%") -> 0 | G40: =SUMIFS(SBLC!$X:$X,SBLC!$T:$T,"Unpaid",SBLC!$R:$R,'DAILY UPDATE SHEET'!$A40,SBLC!$B:$B,$F$36,SBLC!$H:$H,"10%") -> 0 | H40: =SUM(B40:G40) -> 0
A41: =A40+1 -> 46181 | B41: =SUMIFS('LC-Final List'!$W:$W,'LC-Final List'!$AE:$AE,"Unpaid",'LC-Final List'!$Y:$Y,'DAILY UPDATE SHEET'!$A41,'LC-Final List'!$E:$E,'DAILY UPDATE SHEET'!B$36,'LC-Final List'!$F:$F,"10%") -> 1.1980314e+08 | C41: =SUMIFS(SBLC!$X:$X,SBLC!$T:$T,"Unpaid",SBLC!$R:$R,'DAILY UPDATE SHEET'!$A41,SBLC!$B:$B,$B$36,SBLC!$H:$H,"10%") -> 0 | D41: =SUMIFS('LC-Final List'!$W:$W,'LC-Final List'!$AE:$AE,"Unpaid",'LC-Final List'!$Y:$Y,'DAILY UPDATE SHEET'!$A41,'LC-Final List'!$E:$E,'DAILY UPDATE SHEET'!D$36,'LC-Final List'!$F:$F,"10%") -> 0 | E41: =SUMIFS(SBLC!$X:$X,SBLC!$T:$T,"Unpaid",SBLC!$R:$R,'DAILY UPDATE SHEET'!$A41,SBLC!$B:$B,$D$36,SBLC!$H:$H,"10%") -> 0 | F41: =SUMIFS('LC-Final List'!$W:$W,'LC-Final List'!$AE:$AE,"Unpaid",'LC-Final List'!$Y:$Y,'DAILY UPDATE SHEET'!$A41,'LC-Final List'!$E:$E,'DAILY UPDATE SHEET'!F$36,'LC-Final List'!$F:$F,"10%") -> 0 | G41: =SUMIFS(SBLC!$X:$X,SBLC!$T:$T,"Unpaid",SBLC!$R:$R,'DAILY UPDATE SHEET'!$A41,SBLC!$B:$B,$F$36,SBLC!$H:$H,"10%") -> 0 | H41: =SUM(B41:G41) -> 1.1980314e+08
A42: =A41+1 -> 46182 | B42: =SUMIFS('LC-Final List'!$W:$W,'LC-Final List'!$AE:$AE,"Unpaid",'LC-Final List'!$Y:$Y,'DAILY UPDATE SHEET'!$A42,'LC-Final List'!$E:$E,'DAILY UPDATE SHEET'!B$36,'LC-Final List'!$F:$F,"10%") -> 4.5797035e+08 | C42: =SUMIFS(SBLC!$X:$X,SBLC!$T:$T,"Unpaid",SBLC!$R:$R,'DAILY UPDATE SHEET'!$A42,SBLC!$B:$B,$B$36,SBLC!$H:$H,"10%") -> 0 | D42: =SUMIFS('LC-Final List'!$W:$W,'LC-Final List'!$AE:$AE,"Unpaid",'LC-Final List'!$Y:$Y,'DAILY UPDATE SHEET'!$A42,'LC-Final List'!$E:$E,'DAILY UPDATE SHEET'!D$36,'LC-Final List'!$F:$F,"10%") -> 0 | E42: =SUMIFS(SBLC!$X:$X,SBLC!$T:$T,"Unpaid",SBLC!$R:$R,'DAILY UPDATE SHEET'!$A42,SBLC!$B:$B,$D$36,SBLC!$H:$H,"10%") -> 0 | F42: =SUMIFS('LC-Final List'!$W:$W,'LC-Final List'!$AE:$AE,"Unpaid",'LC-Final List'!$Y:$Y,'DAILY UPDATE SHEET'!$A42,'LC-Final List'!$E:$E,'DAILY UPDATE SHEET'!F$36,'LC-Final List'!$F:$F,"10%") -> 72808013 | G42: =SUMIFS(SBLC!$X:$X,SBLC!$T:$T,"Unpaid",SBLC!$R:$R,'DAILY UPDATE SHEET'!$A42,SBLC!$B:$B,$F$36,SBLC!$H:$H,"10%") -> 0 | H42: =SUM(B42:G42) -> 5.3077836e+08
A43: =A42+1 -> 46183 | B43: =SUMIFS('LC-Final List'!$W:$W,'LC-Final List'!$AE:$AE,"Unpaid",'LC-Final List'!$Y:$Y,'DAILY UPDATE SHEET'!$A43,'LC-Final List'!$E:$E,'DAILY UPDATE SHEET'!B$36,'LC-Final List'!$F:$F,"10%") -> 0 | C43: =SUMIFS(SBLC!$X:$X,SBLC!$T:$T,"Unpaid",SBLC!$R:$R,'DAILY UPDATE SHEET'!$A43,SBLC!$B:$B,$B$36,SBLC!$H:$H,"10%") -> 0 | D43: =SUMIFS('LC-Final List'!$W:$W,'LC-Final List'!$AE:$AE,"Unpaid",'LC-Final List'!$Y:$Y,'DAILY UPDATE SHEET'!$A43,'LC-Final List'!$E:$E,'DAILY UPDATE SHEET'!D$36,'LC-Final List'!$F:$F,"10%") -> 0 | E43: =SUMIFS(SBLC!$X:$X,SBLC!$T:$T,"Unpaid",SBLC!$R:$R,'DAILY UPDATE SHEET'!$A43,SBLC!$B:$B,$D$36,SBLC!$H:$H,"10%") -> 0 | F43: =SUMIFS('LC-Final List'!$W:$W,'LC-Final List'!$AE:$AE,"Unpaid",'LC-Final List'!$Y:$Y,'DAILY UPDATE SHEET'!$A43,'LC-Final List'!$E:$E,'DAILY UPDATE SHEET'!F$36,'LC-Final List'!$F:$F,"10%") -> 0 | G43: =SUMIFS(SBLC!$X:$X,SBLC!$T:$T,"Unpaid",SBLC!$R:$R,'DAILY UPDATE SHEET'!$A43,SBLC!$B:$B,$F$36,SBLC!$H:$H,"10%") -> 0 | H43: =SUM(B43:G43) -> 0
A44: =A43+1 -> 46184 | B44: =SUMIFS('LC-Final List'!$W:$W,'LC-Final List'!$AE:$AE,"Unpaid",'LC-Final List'!$Y:$Y,'DAILY UPDATE SHEET'!$A44,'LC-Final List'!$E:$E,'DAILY UPDATE SHEET'!B$36,'LC-Final List'!$F:$F,"10%") -> 2.4195292e+08 | C44: =SUMIFS(SBLC!$X:$X,SBLC!$T:$T,"Unpaid",SBLC!$R:$R,'DAILY UPDATE SHEET'!$A44,SBLC!$B:$B,$B$36,SBLC!$H:$H,"10%") -> 0 | D44: =SUMIFS('LC-Final List'!$W:$W,'LC-Final List'!$AE:$AE,"Unpaid",'LC-Final List'!$Y:$Y,'DAILY UPDATE SHEET'!$A44,'LC-Final List'!$E:$E,'DAILY UPDATE SHEET'!D$36,'LC-Final List'!$F:$F,"10%") -> 0 | E44: =SUMIFS(SBLC!$X:$X,SBLC!$T:$T,"Unpaid",SBLC!$R:$R,'DAILY UPDATE SHEET'!$A44,SBLC!$B:$B,$D$36,SBLC!$H:$H,"10%") -> 0 | F44: =SUMIFS('LC-Final List'!$W:$W,'LC-Final List'!$AE:$AE,"Unpaid",'LC-Final List'!$Y:$Y,'DAILY UPDATE SHEET'!$A44,'LC-Final List'!$E:$E,'DAILY UPDATE SHEET'!F$36,'LC-Final List'!$F:$F,"10%") -> 0 | G44: =SUMIFS(SBLC!$X:$X,SBLC!$T:$T,"Unpaid",SBLC!$R:$R,'DAILY UPDATE SHEET'!$A44,SBLC!$B:$B,$F$36,SBLC!$H:$H,"10%") -> 0 | H44: =SUM(B44:G44) -> 2.4195292e+08
A45: =A44+1 -> 46185 | B45: =SUMIFS('LC-Final List'!$W:$W,'LC-Final List'!$AE:$AE,"Unpaid",'LC-Final List'!$Y:$Y,'DAILY UPDATE SHEET'!$A45,'LC-Final List'!$E:$E,'DAILY UPDATE SHEET'!B$36,'LC-Final List'!$F:$F,"10%") -> 3.7510745e+08 | C45: =SUMIFS(SBLC!$X:$X,SBLC!$T:$T,"Unpaid",SBLC!$R:$R,'DAILY UPDATE SHEET'!$A45,SBLC!$B:$B,$B$36,SBLC!$H:$H,"10%") -> 0 | D45: =SUMIFS('LC-Final List'!$W:$W,'LC-Final List'!$AE:$AE,"Unpaid",'LC-Final List'!$Y:$Y,'DAILY UPDATE SHEET'!$A45,'LC-Final List'!$E:$E,'DAILY UPDATE SHEET'!D$36,'LC-Final List'!$F:$F,"10%") -> 0 | E45: =SUMIFS(SBLC!$X:$X,SBLC!$T:$T,"Unpaid",SBLC!$R:$R,'DAILY UPDATE SHEET'!$A45,SBLC!$B:$B,$D$36,SBLC!$H:$H,"10%") -> 0 | F45: =SUMIFS('LC-Final List'!$W:$W,'LC-Final List'!$AE:$AE,"Unpaid",'LC-Final List'!$Y:$Y,'DAILY UPDATE SHEET'!$A45,'LC-Final List'!$E:$E,'DAILY UPDATE SHEET'!F$36,'LC-Final List'!$F:$F,"10%") -> 169992000 | G45: =SUMIFS(SBLC!$X:$X,SBLC!$T:$T,"Unpaid",SBLC!$R:$R,'DAILY UPDATE SHEET'!$A45,SBLC!$B:$B,$F$36,SBLC!$H:$H,"10%") -> 0 | H45: =SUM(B45:G45) -> 5.4509945e+08
A46: =A45+1 -> 46186 | B46: =SUMIFS('LC-Final List'!$W:$W,'LC-Final List'!$AE:$AE,"Unpaid",'LC-Final List'!$Y:$Y,'DAILY UPDATE SHEET'!$A46,'LC-Final List'!$E:$E,'DAILY UPDATE SHEET'!B$36,'LC-Final List'!$F:$F,"10%") -> 0 | C46: =SUMIFS(SBLC!$X:$X,SBLC!$T:$T,"Unpaid",SBLC!$R:$R,'DAILY UPDATE SHEET'!$A46,SBLC!$B:$B,$B$36,SBLC!$H:$H,"10%") -> 0 | D46: =SUMIFS('LC-Final List'!$W:$W,'LC-Final List'!$AE:$AE,"Unpaid",'LC-Final List'!$Y:$Y,'DAILY UPDATE SHEET'!$A46,'LC-Final List'!$E:$E,'DAILY UPDATE SHEET'!D$36,'LC-Final List'!$F:$F,"10%") -> 0 | E46: =SUMIFS(SBLC!$X:$X,SBLC!$T:$T,"Unpaid",SBLC!$R:$R,'DAILY UPDATE SHEET'!$A46,SBLC!$B:$B,$D$36,SBLC!$H:$H,"10%") -> 0 | F46: =SUMIFS('LC-Final List'!$W:$W,'LC-Final List'!$AE:$AE,"Unpaid",'LC-Final List'!$Y:$Y,'DAILY UPDATE SHEET'!$A46,'LC-Final List'!$E:$E,'DAILY UPDATE SHEET'!F$36,'LC-Final List'!$F:$F,"10%") -> 0 | G46: =SUMIFS(SBLC!$X:$X,SBLC!$T:$T,"Unpaid",SBLC!$R:$R,'DAILY UPDATE SHEET'!$A46,SBLC!$B:$B,$F$36,SBLC!$H:$H,"10%") -> 0 | H46: =SUM(B46:G46) -> 0
...

Sheet SBLC
A1: SBLC REF NO | B1: BANK | C1: SBLC ISSUE DATE | D1: PO NO | E1: LC no. | F1: BILL REF NO | G1: LC Op. Date | H1: Percentage | I1: Supplier Name | J1: Currency | K1: DOCUMENTS RECEIVED | L1: Bill Invoice No | M1: Bill Lodge date | N1: Bill Acceptance date | O1: SBLC Bill Amt (in FC) | P1: Rate | Q1: BOE Bill Amt (in INR) | R1: SBLC LC Payment Due Date | S1: MONTH | T1: Payment Status | U1: Notional Int Amt (USD) | V1: Final Int Amt (USD) | W1: PAYMENT AMT [USD] BILL AMT +INT AMT | X1: Final PAYMENT AMT INR | Y1: FD NO | Z1: LIEN AMT | AA1: FD NO | AB1: LIEN AMT | AC1: FD NO | AD1: LIEN AMT
A2: 0692625TC0A00009 | B2: SBI | C2: 45943 | D2: 5600000237 | E2: 0692625IM0Y00181 | F2: 0692625US0B00519 | G2: 45828 | H2: 0.1 | I2: JIETAI NEW ENERGY TECHNOLOGY (HK) LIMITED | J2: USD | K2: YES | L2: HK-GREW-250808 | M2: 45894 | N2: 45899 | O2: 741181.06 | P2: 90 | Q2: =O2*P2 -> 66706295 | R2: 46030 | S2: =IF(R2="","-",TEXT(R2,"mmmmyy")) -> January26 | T2: Paid | U2: 7889.3573 | V2: 7811 | W2: =V2+O2 -> 748992.06 | Y2: 42039487699 | Z2: 870318 | AA2: 42855164420 | AB2: 308987 | AC2: 44085316349 | AD2: 5418700 | AF2: =Z2+AB2+AD2 -> 6598005 | AG2: =Q2*10% -> 6670629.5 | AH2: =AG2-AF2 -> 72624.54
A3: 0692625TC0A00010 | B3: SBI | C3: 45943 | D3: 5600000264 | E3: 0692625IM0Y00241 | F3: 0692625US0B00561 | G3: 45873 | H3: 1.1 | I3: FLAT HONG KONG CO LTD | J3: USD | K3: YES | L3: 80883796/80875012/80883463/80884631 | M3: 45908 | N3: 45917 | O3: 1111500 | P3: 90 | Q3: =O3*P3 -> 100035000 | R3: 46030 | S3: =IF(R3="","-",TEXT(R3,"mmmmyy")) -> January26 | T3: Paid | U3: 11831.145 | V3: 11713.64 | W3: =V3+O3 -> 1123213.6 | Y3: 44085316349 | Z3: 9894573 | AA3: - | AB3: 0 | AC3: - | AD3: 0 | AF3: =Z3+AB3+AD3 -> 9894573 | AG3: =Q3*10% -> 10003500 | AH3: =AG3-AF3 -> 108927
A4: 0692625TC0A00011 | B4: SBI | C4: 45943 | D4: 5600000268 | E4: 0692625IM0Y00238 | F4: 0692625US0B00546 | G4: 45873 | H4: 1.1 | I4: XINYI PV PRODUCTS (ANHUI) HOLDINGSLTD | J4: USD | K4: YES | L4: 42025080096 | M4: 45901 | N4: 45908 | O4: 83049.5 | P4: 90 | Q4: =O4*P4 -> 7474455 | R4: 46030 | S4: =IF(R4="","-",TEXT(R4,"mmmmyy")) -> January26 | T4: Paid | U4: 884.00421 | V4: 875.22 | W4: =V4+O4 -> 83924.72 | Y4: 44085316349 | Z4: 739307 | AA4: - | AB4: 0 | AC4: - | AD4: 0 | AF4: =Z4+AB4+AD4 -> 739307 | AG4: =Q4*10% -> 747445.5 | AH4: =AG4-AF4 -> 8138.5
A5: 0692625TC0A00012 | B5: SBI | C5: 45943 | D5: 5600000268 | E5: 0692625IM0Y00238 | F5: 0692625US0B00540 | G5: 45873 | H5: 1.1 | I5: XINYI PV PRODUCTS (ANHUI) HOLDINGSLTD | J5: USD | K5: YES | L5: 42025080075 | M5: 45901 | N5: 45908 | O5: 83049.5 | P5: 90 | Q5: =O5*P5 -> 7474455 | R5: 46030 | S5: =IF(R5="","-",TEXT(R5,"mmmmyy")) -> January26 | T5: Paid | U5: 884.00421 | V5: 875.22 | W5: =V5+O5 -> 83924.72 | Y5: 44085316349 | Z5: 3647682 | AA5: - | AB5: 0 | AC5: - | AD5: 0 | AF5: =Z5+AB5+AD5 -> 3647682 | AG5: =Q5*10% -> 747445.5 | AH5: =AG5-AF5 -> -2900236.5
A6: 0692625TC0A00013 | B6: SBI | C6: 45943 | D6: 5600000267 | E6: 0692625IM0Y00237 | F6: 0692625US0B00541 | G6: 45873 | H6: 0.1 | I6: YIBIN YINGFA DEYAO TECHNOLOGY CO LTD | J6: USD | K6: YES | L6: YFDY25080804 | M6: 45901 | N6: 45904 | O6: 409759.8 | P6: 90 | Q6: =O6*P6 -> 36878382 | R6: 46030 | S6: =IF(R6="","-",TEXT(R6,"mmmmyy")) -> January26 | T6: Paid | U6: 4361.6083 | V6: 4318.29 | W6: =V6+O6 -> 414078.09 | Y6: 44085316349 | Z6: 3647682 | AA6: - | AB6: 0 | AC6: - | AD6: 0 | AF6: =Z6+AB6+AD6 -> 3647682 | AG6: =Q6*10% -> 3687838.2 | AH6: =AG6-AF6 -> 40156.2
A7: 0692625TC0A00014 | B7: SBI | C7: 45943 | D7: 5600000251 | E7: 0692625IM0Y00261 | F7: 0692625US0B00559 | G7: 45890 | H7: 0.1 | I7: FLAT HONG KONG CO LTD | J7: USD | K7: YES | L7: 80876299 | M7: 45908 | N7: 45916 | O7: 225540 | P7: 90 | Q7: =O7*P7 -> 20298600 | R7: 46030 | S7: =IF(R7="","-",TEXT(R7,"mmmmyy")) -> January26 | T7: Paid | U7: 2400.7165 | V7: 2376.87 | W7: =V7+O7 -> 227916.87 | Y7: 44085316349 | Z7: 2007757 | AA7: - | AB7: 0 | AC7: - | AD7: 0 | AF7: =Z7+AB7+AD7 -> 2007757 | AG7: =Q7*10% -> 2029860 | AH7: =AG7-AF7 -> 22103
A8: 0692625TC0A00015 | B8: SBI | C8: 45943 | D8: 5600000237 | E8: 0692625IM0Y00181 | F8: 0692625US0B00555 | G8: 45828 | H8: 0.1 | I8: JIETAI NEW ENERGY TECHNOLOGY (HK) LIMITED | J8: USD | K8: YES | L8: HK-GREW-250811 | M8: 45908 | N8: 45911 | O8: 369693.68 | P8: 90 | Q8: =O8*P8 -> 33272431 | R8: 46030 | S8: =IF(R8="","-",TEXT(R8,"mmmmyy")) -> January26 | T8: Paid | U8: 3935.1323 | V8: 3896.05 | W8: =V8+O8 -> 373589.73 | Y8: 42855164420 | Z8: 3291013 | AA8: - | AB8: 0 | AC8: - | AD8: 0 | AF8: =Z8+AB8+AD8 -> 3291013 | AG8: =Q8*10% -> 3327243.1 | AH8: =AG8-AF8 -> 36230.12
A9: 0692625TC0A00021 | B9: SBI | C9: 45945 | D9: 5600000246 | E9: 0692625IM0Y00216 | F9: 0692625US0B00526 | G9: 45856 | H9: 0.1 | I9: JIANGYIN TINZE NEW ENERGY TECHNOLOGY CO., LTD | J9: USD | K9: YES | L9: STG2025-0721 | M9: 45898 | N9: 45903 | O9: 573882 | P9: 90 | Q9: =O9*P9 -> 51649380 | R9: 46035 | S9: =IF(R9="","-",TEXT(R9,"mmmmyy")) -> January26 | T9: Paid | U9: 6303.5629 | V9: 6233.52 | W9: =V9+O9 -> 580115.52 | Y9: 44361399732 | Z9: 941024 | AA9: 44361399732 | AB9: 12645000 | AC9: 44085316349 | AD9: 4167674 | AF9: =Z9+AB9+AD9 -> 17753698 | AG9: =Q9*10% -> 5164938 | AH9: =AG9-AF9 -> -12588760
A10: 0692625TC0A00022 | B10: SBI | C10: 45946 | D10: 5600000264 | E10: 0692625IM0Y00248 | F10: 0692625US0B00627 | G10: 45880 | H10: 0.1 | I10: FLAT HONG KONG CO LTD | J10: USD | K10: YES | L10: 80886515 | M10: 45926 | N10: 45933 | O10: 237315 | P10: 90 | Q10: =O10*P10 -> 21358350 | R10: 46035 | S10: =IF(R10="","-",TEXT(R10,"mmmmyy")) -> January26 | T10: Paid | U10: 2606.6858 | V10: 2570.68 | W10: =V10+O10 -> 239885.68 | Y10: 44361399732 | Z10: 2112578 | AA10: - | AB10: 0 | AC10: - | AD10: 0 | AF10: =Z10+AB10+AD10 -> 2112578 | AG10: =Q10*10% -> 2135835 | AH10: =AG10-AF10 -> 23257
A11: 0692625TC0A00023 | B11: SBI | C11: 45946 | D11: 5600000264 | E11: 0692625IM0Y00246 | F11: 0692625US0B00579 | G11: 45876 | H11: 0.1 | I11: FLAT HONG KONG CO LTD | J11: USD | K11: YES | L11: 80889650 | M11: 45916 | N11: 45920 | O11: 266760 | P11: 90 | Q11: =O11*P11 -> 24008400 | R11: 46035 | S11: =IF(R11="","-",TEXT(R11,"mmmmyy")) -> January26 | T11: Paid | U11: 2930.1118 | V11: 2889.64 | W11: =V11+O11 -> 269649.64 | Y11: 44361399732 | Z11: 2961428 | AA11: - | AB11: 0 | AC11: - | AD11: 0 | AF11: =Z11+AB11+AD11 -> 2961428 | AG11: =Q11*10% -> 2400840 | AH11: =AG11-AF11 -> -560588
A12: 0692625TC0A00024 | B12: SBI | C12: 45946 | D12: 5600000246 | E12: 0692625IM0Y00223 | F12: 0692625US0B00575 | G12: 45863 | H12: 0.1 | I12: JIANGYIN TINZE NEW ENERGY TECHNOLOGY CO., LTD | J12: USD | K12: YES | L12: STG2025-0728 | M12: 45915 | N12: 45917 | O12: 492000 | P12: 90 | Q12: =O12*P12 -> 44280000 | R12: 46035 | S12: =IF(R12="","-",TEXT(R12,"mmmmyy")) -> January26 | T12: Paid | U12: 5404.1649 | V12: 5329.52 | W12: =V12+O12 -> 497329.52 | Y12: 43707298765 | Z12: 4379784 | AA12: - | AB12: 0 | AC12: - | AD12: 0 | AF12: =Z12+AB12+AD12 -> 4379784 | AG12: =Q12*10% -> 4428000 | AH12: =AG12-AF12 -> 48216
A13: 0692625TC0A00025 | B13: SBI | C13: 45946 | D13: 5600000268 | E13: 0692625IM0Y00244 | F13: 0692625US0B00539 | G13: 45876 | H13: 0.1 | I13: XINYI PV PRODUCTS (ANHUI) HOLDINGSLTD | J13: USD | K13: YES | L13: 42025080092/93 | M13: 45901 | N13: 45904 | O13: 332552 | P13: 90 | Q13: =O13*P13 -> 29929680 | R13: 46035 | S13: =IF(R13="","-",TEXT(R13,"mmmmyy")) -> January26 | T13: Paid | U13: 3652.7761 | V13: 3602.32 | W13: =V13+O13 -> 336154.32 | Y13: 43707298765 | Z13: 2960377 | AA13: - | AB13: 0 | AC13: - | AD13: 0 | AF13: =Z13+AB13+AD13 -> 2960377 | AG13: =Q13*10% -> 2992968 | AH13: =AG13-AF13 -> 32591
A14: 0692625TC0A00026 | B14: SBI | C14: 45946 | D14: 5600000268 | E14: 0692625IM0Y00244 | F14: 0692625US0B00556 | G14: 45876 | H14: 0.1 | I14: XINYI PV PRODUCTS (ANHUI) HOLDINGSLTD | J14: USD | K14: YES | L14: 42025080098/99 | M14: 45908 | N14: 45916 | O14: 332670 | P14: 90 | Q14: =O14*P14 -> 29940300 | R14: 46035 | S14: =IF(R14="","-",TEXT(R14,"mmmmyy")) -> January26 | T14: Paid | U14: 3654.0722 | V14: 3603.6 | W14: =V14+O14 -> 336273.6 | AA14: - | AB14: 0 | AC14: - | AD14: 0 | AF14: =Z14+AB14+AD14 -> 0 | AG14: =Q14*10% -> 2994030 | AH14: =AG14-AF14 -> 2994030
A15: 0692625TC0A00027 | B15: SBI | C15: 45946 | D15: 5600000264 | E15: 0692625IM0Y00248 | F15: 0692625US0B00603 | G15: 45880 | H15: 0.1 | I15: FLAT HONG KONG CO LTD | J15: USD | K15: YES | L15: 80881389/80888026/80884223 | M15: 45920 | N15: 45925 | O15: 474630 | P15: 90 | Q15: =O15*P15 -> 42716700 | R15: 46035 | S15: =IF(R15="","-",TEXT(R15,"mmmmyy")) -> January26 | T15: Paid | U15: 5213.3715 | V15: 5141.36 | W15: =V15+O15 -> 479771.36 | Y15: 44361399732 | Z15: 4225156 | AA15: - | AB15: 0 | AC15: - | AD15: 0 | AF15: =Z15+AB15+AD15 -> 4225156 | AG15: =Q15*10% -> 4271670 | AH15: =AG15-AF15 -> 46514
A16: 0692625TC0A00029 | B16: SBI | C16: 45971 | D16: 5600000238 | E16: 0692625IM0Y00220 | F16: 0692625US0B00613 | G16: 45857 | H16: 0.1 | I16: JIETAI NEW ENERGY TECHNOLOGY (HK) LIMITED | J16: USD | K16: YES | L16: HK-GREW-250831 | M16: 45926 | N16: 45933 | O16: 900028.08 | P16: 90 | Q16: =O16*P16 -> 81002527 | R16: 46058 | S16: =IF(R16="","-",TEXT(R16,"mmmmyy")) -> February26 | T16: Paid | U16: 9933.9474 | V16: 9602.82 | W16: =O16+V16 -> 909630.9 | Y16: 43630359430 | Z16: 7581573 | AA16: 43607525170 | AB16: 479978 | AC16: - | AD16: 0 | AF16: =Z16+AB16+AD16 -> 8061551 | AG16: =Q16*10% -> 8100252.7 | AH16: =AG16-AF16 -> 38701.72
A17: 0692625TC0A00032 | B17: SBI | C17: 45971 | D17: 5600000275 | E17: 0692625IM0Y00231 | F17: 0692625US0B00623 | G17: 45867 | H17: 0.1 | I17: JIETAI NEW ENERGY TECHNOLOGY (HK) LIMITED | J17: USD | K17: YES | L17: HK-GREW-250818 | M17: 45925 | N17: 45930 | O17: 825742.11 | P17: 90 | Q17: =O17*P17 -> 74316790 | R17: 46058 | S17: =IF(R17="","-",TEXT(R17,"mmmmyy")) -> February26 | T17: Paid | U17: 9114.0253 | V17: 8810.22 | W17: =O17+V17 -> 834552.33 | Y17: 43630359430 | Z17: 7412687 | AA17: - | AB17: 0 | AC17: - | AD17: 0 | AF17: =Z17+AB17+AD17 -> 7412687 | AG17: =Q17*10% -> 7431679 | AH17: =AG17-AF17 -> 18991.99
A18: 0692625TC0A00030 | B18: SBI | C18: 45971 | D18: 5600000261 | E18: 0692625IM0Y00250 | F18: 0692625US0B00653 | G18: 45882 | H18: 0.1 | I18: JIANGYIN TINZE NEW ENERGY TECHNOLOGY CO., LTD | J18: USD | K18: YES | L18: STG2025-0815/STG2025-0817/STG2025-0818 | M18: 45922 | N18: 45931 | O18: 1230000 | P18: 90 | Q18: =O18*P18 -> 110700000 | R18: 46058 | S18: =IF(R18="","-",TEXT(R18,"mmmmyy")) -> February26 | T18: Paid | U18: 13575.971 | V18: 13123.44 | W18: =O18+V18 -> 1243123.4 | Y18: 43649959856 | Z18: 11029410 | AA18: - | AB18: 0 | AC18: - | AD18: 0 | AF18: =Z18+AB18+AD18 -> 11029410 | AG18: =Q18*10% -> 11070000 | AH18: =AG18-AF18 -> 40590
A19: 0692625TC0A00031 | B19: SBI | C19: 45971 | D19: 5600000259 | E19: 0692625IM0Y00257 | F19: 0692625US0B00618 | G19: 45889 | H19: 0.1 | I19: JIANGSU SULV NEW MATERIAL TECHNOLOGY CO LTD | J19: USD | K19: YES | L19: SL-GREW-2025-8-29 | M19: 45922 | N19: 45925 | O19: 384750 | P19: 90 | Q19: =O19*P19 -> 34627500 | R19: 46058 | S19: =IF(R19="","-",TEXT(R19,"mmmmyy")) -> February26 | T19: Paid | U19: 4246.63 | V19: 4105.08 | W19: =O19+V19 -> 388855.08 | Y19: 43649959856 | Z19: 179863 | AA19: 43792161126 | AB19: 3266342 | AC19: - | AD19: 0 | AF19: =Z19+AB19+AD19 -> 3446205 | AG19: =Q19*10% -> 3462750 | AH19: =AG19-AF19 -> 16545
A20: 0692625TC0A00033 | B20: SBI | C20: 45971 | D20: 5600000261 | E20: 0692625IM0Y00259 | F20: 0692625US0B00616 | G20: 45889 | H20: 0.1 | I20: JIANGYIN TINZE NEW ENERGY TECHNOLOGY CO., LTD | J20: USD | K20: YES | L20: STG2025-0823/STG2025-0822 | M20: 45922 | N20: 45925 | O20: 820000 | P20: 90 | Q20: =O20*P20 -> 73800000 | R20: 46058 | S20: =IF(R20="","-",TEXT(R20,"mmmmyy")) -> February26 | T20: Paid | U20: 9050.6475 | V20: 8748.96 | W20: =O20+V20 -> 828748.96 | Y20: 43630359430 | Z20: 7344740 | AA20: - | AB20: 0 | AC20: - | AD20: 0 | AF20: =Z20+AB20+AD20 -> 7344740 | AG20: =Q20*10% -> 7380000 | AH20: =AG20-AF20 -> 35260
A21: 0692625TC0A00028 | B21: SBI | C21: 45971 | D21: 5600000249 | E21: 0692625IM0Y00260 | F21: 0692625US0B00636 | G21: 45890 | H21: 0.1 | I21: JIANGYIN TINZE NEW ENERGY TECHNOLOGY CO., LTD | J21: USD | K21: YES | L21: STG2025-0828 | M21: 45930 | N21: 45938 | O21: 377432 | P21: 90 | Q21: =O21*P21 -> 33968880 | R21: 46058 | S21: =IF(R21="","-",TEXT(R21,"mmmmyy")) -> February26 | T21: Paid | U21: 4165.8585 | V21: 4027 | W21: =O21+V21 -> 381459 | Y21: 43792161126 | Z21: 3380658 | AA21: - | AB21: 0 | AC21: - | AD21: 0 | AF21: =Z21+AB21+AD21 -> 3380658 | AG21: =Q21*10% -> 3396888 | AH21: =AG21-AF21 -> 16230
A22: 0692625TC0A00034 | B22: SBI | C22: 45975 | D22: 5600000296 | E22: 0692625IM0Y00287 | F22: 0692625US0B00685 | G22: 45918 | H22: 0.1 | I22: FLAT HONG KONG CO LTD | J22: USD | K22: YES | L22: 80906601 | M22: 45954 | N22: 45962 | O22: 568425 | P22: 90 | Q22: =O22*P22 -> 51158250 | R22: 46063 | S22: =IF(R22="","-",TEXT(R22,"mmmmyy")) -> February26 | T22: Paid | U22: 6187.5431 | V22: 6170.47 | W22: =O22+V22 -> 574595.47 | Y22: 43607525170 | Z22: 5054435 | AA22: - | AB22: 0 | AC22: - | AD22: 0 | AF22: =Z22+AB22+AD22 -> 5054435 | AG22: =Q22*10% -> 5115825 | AH22: =AG22-AF22 -> 61390
A23: 0692625TC0A00039 | B23: SBI | C23: 45985 | D23: 5600000238 | E23: 0692625IM0Y00221 | F23: 0692625US0B00642 | G23: 45859 | H23: 0.1 | I23: JIETAI NEW ENERGY TECHNOLOGY (HK) LIMITED | J23: USD | K23: YES | L23: HK-GREW-250918 | M23: 45931 | N23: 45938 | O23: 898101.22 | P23: 90 | Q23: =O23*P23 -> 80829110 | R23: 46072 | S23: =IF(R23="","-",TEXT(R23,"mmmmyy")) -> February26 | T23: Paid | U23: 9940.3864 | V23: 9609.04 | W23: =O23+V23 -> 907710.26 | Y23: 43630359430 | Z23: 8057764 | AA23: - | AB23: 0 | AC23: - | AD23: 0 | AF23: =Z23+AB23+AD23 -> 8057764 | AG23: =Q23*10% -> 8082911 | AH23: =AG23-AF23 -> 25146.98
A24: 0692626TC0A00003 | B24: SBI | C24: 46044 | D24: 5600000294 | E24: 0692625IM0Y00327 | F24: 0692625US0B00744 | G24: 45979 | H24: 0.1 | I24: TAICANG JUREN INTERNATIONAL TRADE CO LTD | J24: USD | K24: YES | L24: JRIT20251119004 | M24: 45995 | N24: 46000 | O24: 602782 | P24: 90 | Q24: =O24*P24 -> 54250380 | R24: 46132 | S24: =IF(R24="","-",TEXT(R24,"mmmmyy")) -> April26 | T24: Paid | U24: 6313.6745 | V24: 6243.52 | W24: =O24+V24 -> 609025.52
A25: 0692626TC0A00004 | B25: SBI | C25: 46044 | D25: 5600000293 | E25: 0692625IM0Y00328 | F25: 0692625US0B00743 | G25: 45979 | H25: 0.1 | I25: TAICANG JUREN INTERNATIONAL TRADE CO LTD | J25: USD | K25: YES | L25: JRIT20251119002 | M25: 45995 | N25: 46000 | O25: 897397 | P25: 90 | Q25: =O25*P25 -> 80765730 | R25: 46132 | S25: =IF(R25="","-",TEXT(R25,"mmmmyy")) -> April26 | T25: Paid | U25: 9399.5389 | V25: 9295.1 | W25: =O25+V25 -> 906692.1
